Traceback (most recent call last):
  File "D:\anaconda3\envs\blog\lib\site-packages\jupyter_cache\executors\utils.py", line 56, in single_nb_execution
    record_timing=False,
  File "D:\anaconda3\envs\blog\lib\site-packages\nbclient\client.py", line 1204, in execute
    return NotebookClient(nb=nb, resources=resources, km=km, **kwargs).execute()
  File "D:\anaconda3\envs\blog\lib\site-packages\nbclient\util.py", line 84, in wrapped
    return just_run(coro(*args, **kwargs))
  File "D:\anaconda3\envs\blog\lib\site-packages\nbclient\util.py", line 62, in just_run
    return loop.run_until_complete(coro)
  File "D:\anaconda3\envs\blog\lib\asyncio\base_events.py", line 587, in run_until_complete
    return future.result()
  File "D:\anaconda3\envs\blog\lib\site-packages\nbclient\client.py", line 664, in async_execute
    cell, index, execution_count=self.code_cells_executed + 1
  File "D:\anaconda3\envs\blog\lib\site-packages\nbclient\client.py", line 965, in async_execute_cell
    await self._check_raise_for_error(cell, cell_index, exec_reply)
  File "D:\anaconda3\envs\blog\lib\site-packages\nbclient\client.py", line 862, in _check_raise_for_error
    raise CellExecutionError.from_cell_and_msg(cell, exec_reply_content)
nbclient.exceptions.CellExecutionError: An error occurred while executing the following cell:
------------------
import numpy as np

np.mean([1, 2, 3])
------------------

[1;31m---------------------------------------------------------------------------[0m
[1;31mImportError[0m                               Traceback (most recent call last)
[1;32mD:\anaconda3\envs\python36\lib\site-packages\numpy\core\__init__.py[0m in [0;36m<module>[1;34m[0m
[0;32m     21[0m [1;32mtry[0m[1;33m:[0m[1;33m[0m[1;33m[0m[0m
[1;32m---> 22[1;33m     [1;32mfrom[0m [1;33m.[0m [1;32mimport[0m [0mmultiarray[0m[1;33m[0m[1;33m[0m[0m
[0m[0;32m     23[0m [1;32mexcept[0m [0mImportError[0m [1;32mas[0m [0mexc[0m[1;33m:[0m[1;33m[0m[1;33m[0m[0m

[1;32mD:\anaconda3\envs\python36\lib\site-packages\numpy\core\multiarray.py[0m in [0;36m<module>[1;34m[0m
[0;32m     11[0m [1;33m[0m[0m
[1;32m---> 12[1;33m [1;32mfrom[0m [1;33m.[0m [1;32mimport[0m [0moverrides[0m[1;33m[0m[1;33m[0m[0m
[0m[0;32m     13[0m [1;32mfrom[0m [1;33m.[0m [1;32mimport[0m [0m_multiarray_umath[0m[1;33m[0m[1;33m[0m[0m

[1;32mD:\anaconda3\envs\python36\lib\site-packages\numpy\core\overrides.py[0m in [0;36m<module>[1;34m[0m
[0;32m      6[0m [1;33m[0m[0m
[1;32m----> 7[1;33m from numpy.core._multiarray_umath import (
[0m[0;32m      8[0m     add_docstring, implement_array_function, _get_implementing_args)

[1;31mImportError[0m: DLL load failed: The specified module could not be found.

During handling of the above exception, another exception occurred:

[1;31mImportError[0m                               Traceback (most recent call last)
[1;32m<ipython-input-1-5a7d51bdf849>[0m in [0;36m<module>[1;34m[0m
[1;32m----> 1[1;33m [1;32mimport[0m [0mnumpy[0m [1;32mas[0m [0mnp[0m[1;33m[0m[1;33m[0m[0m
[0m[0;32m      2[0m [1;33m[0m[0m
[0;32m      3[0m [0mnp[0m[1;33m.[0m[0mmean[0m[1;33m([0m[1;33m[[0m[1;36m1[0m[1;33m,[0m [1;36m2[0m[1;33m,[0m [1;36m3[0m[1;33m][0m[1;33m)[0m[1;33m[0m[1;33m[0m[0m

[1;32mD:\anaconda3\envs\python36\lib\site-packages\numpy\__init__.py[0m in [0;36m<module>[1;34m[0m
[0;32m    138[0m     [1;32mfrom[0m [1;33m.[0m [1;32mimport[0m [0m_distributor_init[0m[1;33m[0m[1;33m[0m[0m
[0;32m    139[0m [1;33m[0m[0m
[1;32m--> 140[1;33m     [1;32mfrom[0m [1;33m.[0m [1;32mimport[0m [0mcore[0m[1;33m[0m[1;33m[0m[0m
[0m[0;32m    141[0m     [1;32mfrom[0m [1;33m.[0m[0mcore[0m [1;32mimport[0m [1;33m*[0m[1;33m[0m[1;33m[0m[0m
[0;32m    142[0m     [1;32mfrom[0m [1;33m.[0m [1;32mimport[0m [0mcompat[0m[1;33m[0m[1;33m[0m[0m

[1;32mD:\anaconda3\envs\python36\lib\site-packages\numpy\core\__init__.py[0m in [0;36m<module>[1;34m[0m
[0;32m     46[0m """ % (sys.version_info[0], sys.version_info[1], sys.executable,
[0;32m     47[0m         __version__, exc)
[1;32m---> 48[1;33m     [1;32mraise[0m [0mImportError[0m[1;33m([0m[0mmsg[0m[1;33m)[0m[1;33m[0m[1;33m[0m[0m
[0m[0;32m     49[0m [1;32mfinally[0m[1;33m:[0m[1;33m[0m[1;33m[0m[0m
[0;32m     50[0m     [1;32mfor[0m [0menvkey[0m [1;32min[0m [0menv_added[0m[1;33m:[0m[1;33m[0m[1;33m[0m[0m

[1;31mImportError[0m: 

IMPORTANT: PLEASE READ THIS FOR ADVICE ON HOW TO SOLVE THIS ISSUE!

Importing the numpy C-extensions failed. This error can happen for
many reasons, often due to issues with your setup or how NumPy was
installed.

We have compiled some common reasons and troubleshooting tips at:

    https://numpy.org/devdocs/user/troubleshooting-importerror.html

Please note and check the following:

  * The Python version is: Python3.6 from "D:\anaconda3\envs\python36\python.exe"
  * The NumPy version is: "1.19.2"

and make sure that they are the versions you expect.
Please carefully study the documentation linked above for further help.

Original error was: DLL load failed: The specified module could not be found.

ImportError: 

IMPORTANT: PLEASE READ THIS FOR ADVICE ON HOW TO SOLVE THIS ISSUE!

Importing the numpy C-extensions failed. This error can happen for
many reasons, often due to issues with your setup or how NumPy was
installed.

We have compiled some common reasons and troubleshooting tips at:

    https://numpy.org/devdocs/user/troubleshooting-importerror.html

Please note and check the following:

  * The Python version is: Python3.6 from "D:\anaconda3\envs\python36\python.exe"
  * The NumPy version is: "1.19.2"

and make sure that they are the versions you expect.
Please carefully study the documentation linked above for further help.

Original error was: DLL load failed: The specified module could not be found.


